2022-05-22 11:48:23,754 [ERROR] -- audit.Archive: HTTPConnectionPool(host='localhost', port=5050): Max retries exceeded with url: /data-images?tags=loli&page=1static/img/__9f3b725aa4c2c2c9b3f2a879508a629d.jpg (Caused by NewConnectionError('<urllib3.connection.HTTPConnection object at 0x7f50f5d316d0>: Failed to establish a new connection: [Errno 111] Connection refused'))
Traceback (most recent call last):
  File "/home/luis/Code_Bakup_LuisEr/4chanshit/img_arch.pkg/env/lib/python3.8/site-packages/urllib3/connection.py", line 174, in _new_conn
    conn = connection.create_connection(
  File "/home/luis/Code_Bakup_LuisEr/4chanshit/img_arch.pkg/env/lib/python3.8/site-packages/urllib3/util/connection.py", line 95, in create_connection
    raise err
  File "/home/luis/Code_Bakup_LuisEr/4chanshit/img_arch.pkg/env/lib/python3.8/site-packages/urllib3/util/connection.py", line 85, in create_connection
    sock.connect(sa)
ConnectionRefusedError: [Errno 111] Connection refused

During handling of the above exception, another exception occurred:

Traceback (most recent call last):
  File "/home/luis/Code_Bakup_LuisEr/4chanshit/img_arch.pkg/env/lib/python3.8/site-packages/urllib3/connectionpool.py", line 703, in urlopen
    httplib_response = self._make_request(
  File "/home/luis/Code_Bakup_LuisEr/4chanshit/img_arch.pkg/env/lib/python3.8/site-packages/urllib3/connectionpool.py", line 398, in _make_request
    conn.request(method, url, **httplib_request_kw)
  File "/home/luis/Code_Bakup_LuisEr/4chanshit/img_arch.pkg/env/lib/python3.8/site-packages/urllib3/connection.py", line 239, in request
    super(HTTPConnection, self).request(method, url, body=body, headers=headers)
  File "/usr/lib64/python3.8/http/client.py", line 1252, in request
    self._send_request(method, url, body, headers, encode_chunked)
  File "/usr/lib64/python3.8/http/client.py", line 1298, in _send_request
    self.endheaders(body, encode_chunked=encode_chunked)
  File "/usr/lib64/python3.8/http/client.py", line 1247, in endheaders
    self._send_output(message_body, encode_chunked=encode_chunked)
  File "/usr/lib64/python3.8/http/client.py", line 1007, in _send_output
    self.send(msg)
  File "/usr/lib64/python3.8/http/client.py", line 947, in send
    self.connect()
  File "/home/luis/Code_Bakup_LuisEr/4chanshit/img_arch.pkg/env/lib/python3.8/site-packages/urllib3/connection.py", line 205, in connect
    conn = self._new_conn()
  File "/home/luis/Code_Bakup_LuisEr/4chanshit/img_arch.pkg/env/lib/python3.8/site-packages/urllib3/connection.py", line 186, in _new_conn
    raise NewConnectionError(
urllib3.exceptions.NewConnectionError: <urllib3.connection.HTTPConnection object at 0x7f50f5d316d0>: Failed to establish a new connection: [Errno 111] Connection refused

During handling of the above exception, another exception occurred:

Traceback (most recent call last):
  File "/home/luis/Code_Bakup_LuisEr/4chanshit/img_arch.pkg/env/lib/python3.8/site-packages/requests/adapters.py", line 440, in send
    resp = conn.urlopen(
  File "/home/luis/Code_Bakup_LuisEr/4chanshit/img_arch.pkg/env/lib/python3.8/site-packages/urllib3/connectionpool.py", line 785, in urlopen
    retries = retries.increment(
  File "/home/luis/Code_Bakup_LuisEr/4chanshit/img_arch.pkg/env/lib/python3.8/site-packages/urllib3/util/retry.py", line 592, in increment
    raise MaxRetryError(_pool, url, error or ResponseError(cause))
urllib3.exceptions.MaxRetryError: HTTPConnectionPool(host='localhost', port=5050): Max retries exceeded with url: /data-images?tags=loli&page=1static/img/__9f3b725aa4c2c2c9b3f2a879508a629d.jpg (Caused by NewConnectionError('<urllib3.connection.HTTPConnection object at 0x7f50f5d316d0>: Failed to establish a new connection: [Errno 111] Connection refused'))

During handling of the above exception, another exception occurred:

Traceback (most recent call last):
  File "client.py", line 26, in inner_func
    response = request(cls, method, url, **kwargs)
  File "client.py", line 90, in request
    return super().request(*args, **kwargs)
  File "/home/luis/Code_Bakup_LuisEr/4chanshit/img_arch.pkg/env/lib/python3.8/site-packages/requests/sessions.py", line 529, in request
    resp = self.send(prep, **send_kwargs)
  File "/home/luis/Code_Bakup_LuisEr/4chanshit/img_arch.pkg/env/lib/python3.8/site-packages/requests/sessions.py", line 645, in send
    r = adapter.send(request, **kwargs)
  File "/home/luis/Code_Bakup_LuisEr/4chanshit/img_arch.pkg/env/lib/python3.8/site-packages/requests/adapters.py", line 519, in send
    raise ConnectionError(e, request=request)
requests.exceptions.ConnectionError: HTTPConnectionPool(host='localhost', port=5050): Max retries exceeded with url: /data-images?tags=loli&page=1static/img/__9f3b725aa4c2c2c9b3f2a879508a629d.jpg (Caused by NewConnectionError('<urllib3.connection.HTTPConnection object at 0x7f50f5d316d0>: Failed to establish a new connection: [Errno 111] Connection refused'))
2022-05-22 11:48:23,767 [ERROR] -- audit.Archive: Server URL: http://localhost:5050/data-images?tags=loli&page=1static/img/__9f3b725aa4c2c2c9b3f2a879508a629d.jpg, failed while trying to connect.
2022-05-22 11:48:23,973 [ERROR] -- audit.Archive: HTTPConnectionPool(host='localhost', port=5050): Max retries exceeded with url: /data-images?tags=loli&page=1static/img/__9f3b725aa4c2c2c9b3f2a879508a629d.jpg (Caused by NewConnectionError('<urllib3.connection.HTTPConnection object at 0x7f50f5ccbe50>: Failed to establish a new connection: [Errno 111] Connection refused'))
Traceback (most recent call last):
  File "/home/luis/Code_Bakup_LuisEr/4chanshit/img_arch.pkg/env/lib/python3.8/site-packages/urllib3/connection.py", line 174, in _new_conn
    conn = connection.create_connection(
  File "/home/luis/Code_Bakup_LuisEr/4chanshit/img_arch.pkg/env/lib/python3.8/site-packages/urllib3/util/connection.py", line 95, in create_connection
    raise err
  File "/home/luis/Code_Bakup_LuisEr/4chanshit/img_arch.pkg/env/lib/python3.8/site-packages/urllib3/util/connection.py", line 85, in create_connection
    sock.connect(sa)
ConnectionRefusedError: [Errno 111] Connection refused

During handling of the above exception, another exception occurred:

Traceback (most recent call last):
  File "/home/luis/Code_Bakup_LuisEr/4chanshit/img_arch.pkg/env/lib/python3.8/site-packages/urllib3/connectionpool.py", line 703, in urlopen
    httplib_response = self._make_request(
  File "/home/luis/Code_Bakup_LuisEr/4chanshit/img_arch.pkg/env/lib/python3.8/site-packages/urllib3/connectionpool.py", line 398, in _make_request
    conn.request(method, url, **httplib_request_kw)
  File "/home/luis/Code_Bakup_LuisEr/4chanshit/img_arch.pkg/env/lib/python3.8/site-packages/urllib3/connection.py", line 239, in request
    super(HTTPConnection, self).request(method, url, body=body, headers=headers)
  File "/usr/lib64/python3.8/http/client.py", line 1252, in request
    self._send_request(method, url, body, headers, encode_chunked)
  File "/usr/lib64/python3.8/http/client.py", line 1298, in _send_request
    self.endheaders(body, encode_chunked=encode_chunked)
  File "/usr/lib64/python3.8/http/client.py", line 1247, in endheaders
    self._send_output(message_body, encode_chunked=encode_chunked)
  File "/usr/lib64/python3.8/http/client.py", line 1007, in _send_output
    self.send(msg)
  File "/usr/lib64/python3.8/http/client.py", line 947, in send
    self.connect()
  File "/home/luis/Code_Bakup_LuisEr/4chanshit/img_arch.pkg/env/lib/python3.8/site-packages/urllib3/connection.py", line 205, in connect
    conn = self._new_conn()
  File "/home/luis/Code_Bakup_LuisEr/4chanshit/img_arch.pkg/env/lib/python3.8/site-packages/urllib3/connection.py", line 186, in _new_conn
    raise NewConnectionError(
urllib3.exceptions.NewConnectionError: <urllib3.connection.HTTPConnection object at 0x7f50f5ccbe50>: Failed to establish a new connection: [Errno 111] Connection refused

During handling of the above exception, another exception occurred:

Traceback (most recent call last):
  File "/home/luis/Code_Bakup_LuisEr/4chanshit/img_arch.pkg/env/lib/python3.8/site-packages/requests/adapters.py", line 440, in send
    resp = conn.urlopen(
  File "/home/luis/Code_Bakup_LuisEr/4chanshit/img_arch.pkg/env/lib/python3.8/site-packages/urllib3/connectionpool.py", line 785, in urlopen
    retries = retries.increment(
  File "/home/luis/Code_Bakup_LuisEr/4chanshit/img_arch.pkg/env/lib/python3.8/site-packages/urllib3/util/retry.py", line 592, in increment
    raise MaxRetryError(_pool, url, error or ResponseError(cause))
urllib3.exceptions.MaxRetryError: HTTPConnectionPool(host='localhost', port=5050): Max retries exceeded with url: /data-images?tags=loli&page=1static/img/__9f3b725aa4c2c2c9b3f2a879508a629d.jpg (Caused by NewConnectionError('<urllib3.connection.HTTPConnection object at 0x7f50f5ccbe50>: Failed to establish a new connection: [Errno 111] Connection refused'))

During handling of the above exception, another exception occurred:

Traceback (most recent call last):
  File "client.py", line 26, in inner_func
    response = request(cls, method, url, **kwargs)
  File "client.py", line 90, in request
    return super().request(*args, **kwargs)
  File "/home/luis/Code_Bakup_LuisEr/4chanshit/img_arch.pkg/env/lib/python3.8/site-packages/requests/sessions.py", line 529, in request
    resp = self.send(prep, **send_kwargs)
  File "/home/luis/Code_Bakup_LuisEr/4chanshit/img_arch.pkg/env/lib/python3.8/site-packages/requests/sessions.py", line 645, in send
    r = adapter.send(request, **kwargs)
  File "/home/luis/Code_Bakup_LuisEr/4chanshit/img_arch.pkg/env/lib/python3.8/site-packages/requests/adapters.py", line 519, in send
    raise ConnectionError(e, request=request)
requests.exceptions.ConnectionError: HTTPConnectionPool(host='localhost', port=5050): Max retries exceeded with url: /data-images?tags=loli&page=1static/img/__9f3b725aa4c2c2c9b3f2a879508a629d.jpg (Caused by NewConnectionError('<urllib3.connection.HTTPConnection object at 0x7f50f5ccbe50>: Failed to establish a new connection: [Errno 111] Connection refused'))
2022-05-22 11:48:23,974 [ERROR] -- audit.Archive: Server URL: http://localhost:5050/data-images?tags=loli&page=1static/img/__9f3b725aa4c2c2c9b3f2a879508a629d.jpg, failed while trying to connect.
2022-05-22 11:48:24,180 [ERROR] -- audit.Archive: HTTPConnectionPool(host='localhost', port=5050): Max retries exceeded with url: /data-images?tags=loli&page=1static/img/__9f3b725aa4c2c2c9b3f2a879508a629d.jpg (Caused by NewConnectionError('<urllib3.connection.HTTPConnection object at 0x7f50f5d198e0>: Failed to establish a new connection: [Errno 111] Connection refused'))
Traceback (most recent call last):
  File "/home/luis/Code_Bakup_LuisEr/4chanshit/img_arch.pkg/env/lib/python3.8/site-packages/urllib3/connection.py", line 174, in _new_conn
    conn = connection.create_connection(
  File "/home/luis/Code_Bakup_LuisEr/4chanshit/img_arch.pkg/env/lib/python3.8/site-packages/urllib3/util/connection.py", line 95, in create_connection
    raise err
  File "/home/luis/Code_Bakup_LuisEr/4chanshit/img_arch.pkg/env/lib/python3.8/site-packages/urllib3/util/connection.py", line 85, in create_connection
    sock.connect(sa)
ConnectionRefusedError: [Errno 111] Connection refused

During handling of the above exception, another exception occurred:

Traceback (most recent call last):
  File "/home/luis/Code_Bakup_LuisEr/4chanshit/img_arch.pkg/env/lib/python3.8/site-packages/urllib3/connectionpool.py", line 703, in urlopen
    httplib_response = self._make_request(
  File "/home/luis/Code_Bakup_LuisEr/4chanshit/img_arch.pkg/env/lib/python3.8/site-packages/urllib3/connectionpool.py", line 398, in _make_request
    conn.request(method, url, **httplib_request_kw)
  File "/home/luis/Code_Bakup_LuisEr/4chanshit/img_arch.pkg/env/lib/python3.8/site-packages/urllib3/connection.py", line 239, in request
    super(HTTPConnection, self).request(method, url, body=body, headers=headers)
  File "/usr/lib64/python3.8/http/client.py", line 1252, in request
    self._send_request(method, url, body, headers, encode_chunked)
  File "/usr/lib64/python3.8/http/client.py", line 1298, in _send_request
    self.endheaders(body, encode_chunked=encode_chunked)
  File "/usr/lib64/python3.8/http/client.py", line 1247, in endheaders
    self._send_output(message_body, encode_chunked=encode_chunked)
  File "/usr/lib64/python3.8/http/client.py", line 1007, in _send_output
    self.send(msg)
  File "/usr/lib64/python3.8/http/client.py", line 947, in send
    self.connect()
  File "/home/luis/Code_Bakup_LuisEr/4chanshit/img_arch.pkg/env/lib/python3.8/site-packages/urllib3/connection.py", line 205, in connect
    conn = self._new_conn()
  File "/home/luis/Code_Bakup_LuisEr/4chanshit/img_arch.pkg/env/lib/python3.8/site-packages/urllib3/connection.py", line 186, in _new_conn
    raise NewConnectionError(
urllib3.exceptions.NewConnectionError: <urllib3.connection.HTTPConnection object at 0x7f50f5d198e0>: Failed to establish a new connection: [Errno 111] Connection refused

During handling of the above exception, another exception occurred:

Traceback (most recent call last):
  File "/home/luis/Code_Bakup_LuisEr/4chanshit/img_arch.pkg/env/lib/python3.8/site-packages/requests/adapters.py", line 440, in send
    resp = conn.urlopen(
  File "/home/luis/Code_Bakup_LuisEr/4chanshit/img_arch.pkg/env/lib/python3.8/site-packages/urllib3/connectionpool.py", line 785, in urlopen
    retries = retries.increment(
  File "/home/luis/Code_Bakup_LuisEr/4chanshit/img_arch.pkg/env/lib/python3.8/site-packages/urllib3/util/retry.py", line 592, in increment
    raise MaxRetryError(_pool, url, error or ResponseError(cause))
urllib3.exceptions.MaxRetryError: HTTPConnectionPool(host='localhost', port=5050): Max retries exceeded with url: /data-images?tags=loli&page=1static/img/__9f3b725aa4c2c2c9b3f2a879508a629d.jpg (Caused by NewConnectionError('<urllib3.connection.HTTPConnection object at 0x7f50f5d198e0>: Failed to establish a new connection: [Errno 111] Connection refused'))

During handling of the above exception, another exception occurred:

Traceback (most recent call last):
  File "client.py", line 26, in inner_func
    response = request(cls, method, url, **kwargs)
  File "client.py", line 90, in request
    return super().request(*args, **kwargs)
  File "/home/luis/Code_Bakup_LuisEr/4chanshit/img_arch.pkg/env/lib/python3.8/site-packages/requests/sessions.py", line 529, in request
    resp = self.send(prep, **send_kwargs)
  File "/home/luis/Code_Bakup_LuisEr/4chanshit/img_arch.pkg/env/lib/python3.8/site-packages/requests/sessions.py", line 645, in send
    r = adapter.send(request, **kwargs)
  File "/home/luis/Code_Bakup_LuisEr/4chanshit/img_arch.pkg/env/lib/python3.8/site-packages/requests/adapters.py", line 519, in send
    raise ConnectionError(e, request=request)
requests.exceptions.ConnectionError: HTTPConnectionPool(host='localhost', port=5050): Max retries exceeded with url: /data-images?tags=loli&page=1static/img/__9f3b725aa4c2c2c9b3f2a879508a629d.jpg (Caused by NewConnectionError('<urllib3.connection.HTTPConnection object at 0x7f50f5d198e0>: Failed to establish a new connection: [Errno 111] Connection refused'))
2022-05-22 11:48:24,182 [ERROR] -- audit.Archive: Server URL: http://localhost:5050/data-images?tags=loli&page=1static/img/__9f3b725aa4c2c2c9b3f2a879508a629d.jpg, failed while trying to connect.
2022-05-22 11:48:24,388 [ERROR] -- audit.Archive: HTTPConnectionPool(host='localhost', port=5050): Max retries exceeded with url: /data-images?tags=loli&page=1static/img/__9f3b725aa4c2c2c9b3f2a879508a629d.jpg (Caused by NewConnectionError('<urllib3.connection.HTTPConnection object at 0x7f50f5cebee0>: Failed to establish a new connection: [Errno 111] Connection refused'))
Traceback (most recent call last):
  File "/home/luis/Code_Bakup_LuisEr/4chanshit/img_arch.pkg/env/lib/python3.8/site-packages/urllib3/connection.py", line 174, in _new_conn
    conn = connection.create_connection(
  File "/home/luis/Code_Bakup_LuisEr/4chanshit/img_arch.pkg/env/lib/python3.8/site-packages/urllib3/util/connection.py", line 95, in create_connection
    raise err
  File "/home/luis/Code_Bakup_LuisEr/4chanshit/img_arch.pkg/env/lib/python3.8/site-packages/urllib3/util/connection.py", line 85, in create_connection
    sock.connect(sa)
ConnectionRefusedError: [Errno 111] Connection refused

During handling of the above exception, another exception occurred:

Traceback (most recent call last):
  File "/home/luis/Code_Bakup_LuisEr/4chanshit/img_arch.pkg/env/lib/python3.8/site-packages/urllib3/connectionpool.py", line 703, in urlopen
    httplib_response = self._make_request(
  File "/home/luis/Code_Bakup_LuisEr/4chanshit/img_arch.pkg/env/lib/python3.8/site-packages/urllib3/connectionpool.py", line 398, in _make_request
    conn.request(method, url, **httplib_request_kw)
  File "/home/luis/Code_Bakup_LuisEr/4chanshit/img_arch.pkg/env/lib/python3.8/site-packages/urllib3/connection.py", line 239, in request
    super(HTTPConnection, self).request(method, url, body=body, headers=headers)
  File "/usr/lib64/python3.8/http/client.py", line 1252, in request
    self._send_request(method, url, body, headers, encode_chunked)
  File "/usr/lib64/python3.8/http/client.py", line 1298, in _send_request
    self.endheaders(body, encode_chunked=encode_chunked)
  File "/usr/lib64/python3.8/http/client.py", line 1247, in endheaders
    self._send_output(message_body, encode_chunked=encode_chunked)
  File "/usr/lib64/python3.8/http/client.py", line 1007, in _send_output
    self.send(msg)
  File "/usr/lib64/python3.8/http/client.py", line 947, in send
    self.connect()
  File "/home/luis/Code_Bakup_LuisEr/4chanshit/img_arch.pkg/env/lib/python3.8/site-packages/urllib3/connection.py", line 205, in connect
    conn = self._new_conn()
  File "/home/luis/Code_Bakup_LuisEr/4chanshit/img_arch.pkg/env/lib/python3.8/site-packages/urllib3/connection.py", line 186, in _new_conn
    raise NewConnectionError(
urllib3.exceptions.NewConnectionError: <urllib3.connection.HTTPConnection object at 0x7f50f5cebee0>: Failed to establish a new connection: [Errno 111] Connection refused

During handling of the above exception, another exception occurred:

Traceback (most recent call last):
  File "/home/luis/Code_Bakup_LuisEr/4chanshit/img_arch.pkg/env/lib/python3.8/site-packages/requests/adapters.py", line 440, in send
    resp = conn.urlopen(
  File "/home/luis/Code_Bakup_LuisEr/4chanshit/img_arch.pkg/env/lib/python3.8/site-packages/urllib3/connectionpool.py", line 785, in urlopen
    retries = retries.increment(
  File "/home/luis/Code_Bakup_LuisEr/4chanshit/img_arch.pkg/env/lib/python3.8/site-packages/urllib3/util/retry.py", line 592, in increment
    raise MaxRetryError(_pool, url, error or ResponseError(cause))
urllib3.exceptions.MaxRetryError: HTTPConnectionPool(host='localhost', port=5050): Max retries exceeded with url: /data-images?tags=loli&page=1static/img/__9f3b725aa4c2c2c9b3f2a879508a629d.jpg (Caused by NewConnectionError('<urllib3.connection.HTTPConnection object at 0x7f50f5cebee0>: Failed to establish a new connection: [Errno 111] Connection refused'))

During handling of the above exception, another exception occurred:

Traceback (most recent call last):
  File "client.py", line 26, in inner_func
    response = request(cls, method, url, **kwargs)
  File "client.py", line 90, in request
    return super().request(*args, **kwargs)
  File "/home/luis/Code_Bakup_LuisEr/4chanshit/img_arch.pkg/env/lib/python3.8/site-packages/requests/sessions.py", line 529, in request
    resp = self.send(prep, **send_kwargs)
  File "/home/luis/Code_Bakup_LuisEr/4chanshit/img_arch.pkg/env/lib/python3.8/site-packages/requests/sessions.py", line 645, in send
    r = adapter.send(request, **kwargs)
  File "/home/luis/Code_Bakup_LuisEr/4chanshit/img_arch.pkg/env/lib/python3.8/site-packages/requests/adapters.py", line 519, in send
    raise ConnectionError(e, request=request)
requests.exceptions.ConnectionError: HTTPConnectionPool(host='localhost', port=5050): Max retries exceeded with url: /data-images?tags=loli&page=1static/img/__9f3b725aa4c2c2c9b3f2a879508a629d.jpg (Caused by NewConnectionError('<urllib3.connection.HTTPConnection object at 0x7f50f5cebee0>: Failed to establish a new connection: [Errno 111] Connection refused'))
2022-05-22 11:48:24,389 [ERROR] -- audit.Archive: Server URL: http://localhost:5050/data-images?tags=loli&page=1static/img/__9f3b725aa4c2c2c9b3f2a879508a629d.jpg, failed while trying to connect.
2022-05-22 11:48:24,597 [ERROR] -- audit.Archive: HTTPConnectionPool(host='localhost', port=5050): Max retries exceeded with url: /data-images?tags=loli&page=1static/img/__9f3b725aa4c2c2c9b3f2a879508a629d.jpg (Caused by NewConnectionError('<urllib3.connection.HTTPConnection object at 0x7f50f5c7e4f0>: Failed to establish a new connection: [Errno 111] Connection refused'))
Traceback (most recent call last):
  File "/home/luis/Code_Bakup_LuisEr/4chanshit/img_arch.pkg/env/lib/python3.8/site-packages/urllib3/connection.py", line 174, in _new_conn
    conn = connection.create_connection(
  File "/home/luis/Code_Bakup_LuisEr/4chanshit/img_arch.pkg/env/lib/python3.8/site-packages/urllib3/util/connection.py", line 95, in create_connection
    raise err
  File "/home/luis/Code_Bakup_LuisEr/4chanshit/img_arch.pkg/env/lib/python3.8/site-packages/urllib3/util/connection.py", line 85, in create_connection
    sock.connect(sa)
ConnectionRefusedError: [Errno 111] Connection refused

During handling of the above exception, another exception occurred:

Traceback (most recent call last):
  File "/home/luis/Code_Bakup_LuisEr/4chanshit/img_arch.pkg/env/lib/python3.8/site-packages/urllib3/connectionpool.py", line 703, in urlopen
    httplib_response = self._make_request(
  File "/home/luis/Code_Bakup_LuisEr/4chanshit/img_arch.pkg/env/lib/python3.8/site-packages/urllib3/connectionpool.py", line 398, in _make_request
    conn.request(method, url, **httplib_request_kw)
  File "/home/luis/Code_Bakup_LuisEr/4chanshit/img_arch.pkg/env/lib/python3.8/site-packages/urllib3/connection.py", line 239, in request
    super(HTTPConnection, self).request(method, url, body=body, headers=headers)
  File "/usr/lib64/python3.8/http/client.py", line 1252, in request
    self._send_request(method, url, body, headers, encode_chunked)
  File "/usr/lib64/python3.8/http/client.py", line 1298, in _send_request
    self.endheaders(body, encode_chunked=encode_chunked)
  File "/usr/lib64/python3.8/http/client.py", line 1247, in endheaders
    self._send_output(message_body, encode_chunked=encode_chunked)
  File "/usr/lib64/python3.8/http/client.py", line 1007, in _send_output
    self.send(msg)
  File "/usr/lib64/python3.8/http/client.py", line 947, in send
    self.connect()
  File "/home/luis/Code_Bakup_LuisEr/4chanshit/img_arch.pkg/env/lib/python3.8/site-packages/urllib3/connection.py", line 205, in connect
    conn = self._new_conn()
  File "/home/luis/Code_Bakup_LuisEr/4chanshit/img_arch.pkg/env/lib/python3.8/site-packages/urllib3/connection.py", line 186, in _new_conn
    raise NewConnectionError(
urllib3.exceptions.NewConnectionError: <urllib3.connection.HTTPConnection object at 0x7f50f5c7e4f0>: Failed to establish a new connection: [Errno 111] Connection refused

During handling of the above exception, another exception occurred:

Traceback (most recent call last):
  File "/home/luis/Code_Bakup_LuisEr/4chanshit/img_arch.pkg/env/lib/python3.8/site-packages/requests/adapters.py", line 440, in send
    resp = conn.urlopen(
  File "/home/luis/Code_Bakup_LuisEr/4chanshit/img_arch.pkg/env/lib/python3.8/site-packages/urllib3/connectionpool.py", line 785, in urlopen
    retries = retries.increment(
  File "/home/luis/Code_Bakup_LuisEr/4chanshit/img_arch.pkg/env/lib/python3.8/site-packages/urllib3/util/retry.py", line 592, in increment
    raise MaxRetryError(_pool, url, error or ResponseError(cause))
urllib3.exceptions.MaxRetryError: HTTPConnectionPool(host='localhost', port=5050): Max retries exceeded with url: /data-images?tags=loli&page=1static/img/__9f3b725aa4c2c2c9b3f2a879508a629d.jpg (Caused by NewConnectionError('<urllib3.connection.HTTPConnection object at 0x7f50f5c7e4f0>: Failed to establish a new connection: [Errno 111] Connection refused'))

During handling of the above exception, another exception occurred:

Traceback (most recent call last):
  File "client.py", line 26, in inner_func
    response = request(cls, method, url, **kwargs)
  File "client.py", line 90, in request
    return super().request(*args, **kwargs)
  File "/home/luis/Code_Bakup_LuisEr/4chanshit/img_arch.pkg/env/lib/python3.8/site-packages/requests/sessions.py", line 529, in request
    resp = self.send(prep, **send_kwargs)
  File "/home/luis/Code_Bakup_LuisEr/4chanshit/img_arch.pkg/env/lib/python3.8/site-packages/requests/sessions.py", line 645, in send
    r = adapter.send(request, **kwargs)
  File "/home/luis/Code_Bakup_LuisEr/4chanshit/img_arch.pkg/env/lib/python3.8/site-packages/requests/adapters.py", line 519, in send
    raise ConnectionError(e, request=request)
requests.exceptions.ConnectionError: HTTPConnectionPool(host='localhost', port=5050): Max retries exceeded with url: /data-images?tags=loli&page=1static/img/__9f3b725aa4c2c2c9b3f2a879508a629d.jpg (Caused by NewConnectionError('<urllib3.connection.HTTPConnection object at 0x7f50f5c7e4f0>: Failed to establish a new connection: [Errno 111] Connection refused'))
2022-05-22 11:48:24,599 [ERROR] -- audit.Archive: Server URL: http://localhost:5050/data-images?tags=loli&page=1static/img/__9f3b725aa4c2c2c9b3f2a879508a629d.jpg, failed while trying to connect.
2022-05-22 11:48:24,804 [ERROR] -- audit.Archive: HTTPConnectionPool(host='localhost', port=5050): Max retries exceeded with url: /data-images?tags=loli&page=1static/img/__9f3b725aa4c2c2c9b3f2a879508a629d.jpg (Caused by NewConnectionError('<urllib3.connection.HTTPConnection object at 0x7f50f5cebee0>: Failed to establish a new connection: [Errno 111] Connection refused'))
Traceback (most recent call last):
  File "/home/luis/Code_Bakup_LuisEr/4chanshit/img_arch.pkg/env/lib/python3.8/site-packages/urllib3/connection.py", line 174, in _new_conn
    conn = connection.create_connection(
  File "/home/luis/Code_Bakup_LuisEr/4chanshit/img_arch.pkg/env/lib/python3.8/site-packages/urllib3/util/connection.py", line 95, in create_connection
    raise err
  File "/home/luis/Code_Bakup_LuisEr/4chanshit/img_arch.pkg/env/lib/python3.8/site-packages/urllib3/util/connection.py", line 85, in create_connection
    sock.connect(sa)
ConnectionRefusedError: [Errno 111] Connection refused

During handling of the above exception, another exception occurred:

Traceback (most recent call last):
  File "/home/luis/Code_Bakup_LuisEr/4chanshit/img_arch.pkg/env/lib/python3.8/site-packages/urllib3/connectionpool.py", line 703, in urlopen
    httplib_response = self._make_request(
  File "/home/luis/Code_Bakup_LuisEr/4chanshit/img_arch.pkg/env/lib/python3.8/site-packages/urllib3/connectionpool.py", line 398, in _make_request
    conn.request(method, url, **httplib_request_kw)
  File "/home/luis/Code_Bakup_LuisEr/4chanshit/img_arch.pkg/env/lib/python3.8/site-packages/urllib3/connection.py", line 239, in request
    super(HTTPConnection, self).request(method, url, body=body, headers=headers)
  File "/usr/lib64/python3.8/http/client.py", line 1252, in request
    self._send_request(method, url, body, headers, encode_chunked)
  File "/usr/lib64/python3.8/http/client.py", line 1298, in _send_request
    self.endheaders(body, encode_chunked=encode_chunked)
  File "/usr/lib64/python3.8/http/client.py", line 1247, in endheaders
    self._send_output(message_body, encode_chunked=encode_chunked)
  File "/usr/lib64/python3.8/http/client.py", line 1007, in _send_output
    self.send(msg)
  File "/usr/lib64/python3.8/http/client.py", line 947, in send
    self.connect()
  File "/home/luis/Code_Bakup_LuisEr/4chanshit/img_arch.pkg/env/lib/python3.8/site-packages/urllib3/connection.py", line 205, in connect
    conn = self._new_conn()
  File "/home/luis/Code_Bakup_LuisEr/4chanshit/img_arch.pkg/env/lib/python3.8/site-packages/urllib3/connection.py", line 186, in _new_conn
    raise NewConnectionError(
urllib3.exceptions.NewConnectionError: <urllib3.connection.HTTPConnection object at 0x7f50f5cebee0>: Failed to establish a new connection: [Errno 111] Connection refused

During handling of the above exception, another exception occurred:

Traceback (most recent call last):
  File "/home/luis/Code_Bakup_LuisEr/4chanshit/img_arch.pkg/env/lib/python3.8/site-packages/requests/adapters.py", line 440, in send
    resp = conn.urlopen(
  File "/home/luis/Code_Bakup_LuisEr/4chanshit/img_arch.pkg/env/lib/python3.8/site-packages/urllib3/connectionpool.py", line 785, in urlopen
    retries = retries.increment(
  File "/home/luis/Code_Bakup_LuisEr/4chanshit/img_arch.pkg/env/lib/python3.8/site-packages/urllib3/util/retry.py", line 592, in increment
    raise MaxRetryError(_pool, url, error or ResponseError(cause))
urllib3.exceptions.MaxRetryError: HTTPConnectionPool(host='localhost', port=5050): Max retries exceeded with url: /data-images?tags=loli&page=1static/img/__9f3b725aa4c2c2c9b3f2a879508a629d.jpg (Caused by NewConnectionError('<urllib3.connection.HTTPConnection object at 0x7f50f5cebee0>: Failed to establish a new connection: [Errno 111] Connection refused'))

During handling of the above exception, another exception occurred:

Traceback (most recent call last):
  File "client.py", line 26, in inner_func
    response = request(cls, method, url, **kwargs)
  File "client.py", line 90, in request
    return super().request(*args, **kwargs)
  File "/home/luis/Code_Bakup_LuisEr/4chanshit/img_arch.pkg/env/lib/python3.8/site-packages/requests/sessions.py", line 529, in request
    resp = self.send(prep, **send_kwargs)
  File "/home/luis/Code_Bakup_LuisEr/4chanshit/img_arch.pkg/env/lib/python3.8/site-packages/requests/sessions.py", line 645, in send
    r = adapter.send(request, **kwargs)
  File "/home/luis/Code_Bakup_LuisEr/4chanshit/img_arch.pkg/env/lib/python3.8/site-packages/requests/adapters.py", line 519, in send
    raise ConnectionError(e, request=request)
requests.exceptions.ConnectionError: HTTPConnectionPool(host='localhost', port=5050): Max retries exceeded with url: /data-images?tags=loli&page=1static/img/__9f3b725aa4c2c2c9b3f2a879508a629d.jpg (Caused by NewConnectionError('<urllib3.connection.HTTPConnection object at 0x7f50f5cebee0>: Failed to establish a new connection: [Errno 111] Connection refused'))
2022-05-22 11:48:24,806 [ERROR] -- audit.Archive: Server URL: http://localhost:5050/data-images?tags=loli&page=1static/img/__9f3b725aa4c2c2c9b3f2a879508a629d.jpg, failed while trying to connect.
2022-05-22 11:48:25,012 [ERROR] -- audit.Archive: HTTPConnectionPool(host='localhost', port=5050): Max retries exceeded with url: /data-images?tags=loli&page=1static/img/__9f3b725aa4c2c2c9b3f2a879508a629d.jpg (Caused by NewConnectionError('<urllib3.connection.HTTPConnection object at 0x7f50f5d197f0>: Failed to establish a new connection: [Errno 111] Connection refused'))
Traceback (most recent call last):
  File "/home/luis/Code_Bakup_LuisEr/4chanshit/img_arch.pkg/env/lib/python3.8/site-packages/urllib3/connection.py", line 174, in _new_conn
    conn = connection.create_connection(
  File "/home/luis/Code_Bakup_LuisEr/4chanshit/img_arch.pkg/env/lib/python3.8/site-packages/urllib3/util/connection.py", line 95, in create_connection
    raise err
  File "/home/luis/Code_Bakup_LuisEr/4chanshit/img_arch.pkg/env/lib/python3.8/site-packages/urllib3/util/connection.py", line 85, in create_connection
    sock.connect(sa)
ConnectionRefusedError: [Errno 111] Connection refused

During handling of the above exception, another exception occurred:

Traceback (most recent call last):
  File "/home/luis/Code_Bakup_LuisEr/4chanshit/img_arch.pkg/env/lib/python3.8/site-packages/urllib3/connectionpool.py", line 703, in urlopen
    httplib_response = self._make_request(
  File "/home/luis/Code_Bakup_LuisEr/4chanshit/img_arch.pkg/env/lib/python3.8/site-packages/urllib3/connectionpool.py", line 398, in _make_request
    conn.request(method, url, **httplib_request_kw)
  File "/home/luis/Code_Bakup_LuisEr/4chanshit/img_arch.pkg/env/lib/python3.8/site-packages/urllib3/connection.py", line 239, in request
    super(HTTPConnection, self).request(method, url, body=body, headers=headers)
  File "/usr/lib64/python3.8/http/client.py", line 1252, in request
    self._send_request(method, url, body, headers, encode_chunked)
  File "/usr/lib64/python3.8/http/client.py", line 1298, in _send_request
    self.endheaders(body, encode_chunked=encode_chunked)
  File "/usr/lib64/python3.8/http/client.py", line 1247, in endheaders
    self._send_output(message_body, encode_chunked=encode_chunked)
  File "/usr/lib64/python3.8/http/client.py", line 1007, in _send_output
    self.send(msg)
  File "/usr/lib64/python3.8/http/client.py", line 947, in send
    self.connect()
  File "/home/luis/Code_Bakup_LuisEr/4chanshit/img_arch.pkg/env/lib/python3.8/site-packages/urllib3/connection.py", line 205, in connect
    conn = self._new_conn()
  File "/home/luis/Code_Bakup_LuisEr/4chanshit/img_arch.pkg/env/lib/python3.8/site-packages/urllib3/connection.py", line 186, in _new_conn
    raise NewConnectionError(
urllib3.exceptions.NewConnectionError: <urllib3.connection.HTTPConnection object at 0x7f50f5d197f0>: Failed to establish a new connection: [Errno 111] Connection refused

During handling of the above exception, another exception occurred:

Traceback (most recent call last):
  File "/home/luis/Code_Bakup_LuisEr/4chanshit/img_arch.pkg/env/lib/python3.8/site-packages/requests/adapters.py", line 440, in send
    resp = conn.urlopen(
  File "/home/luis/Code_Bakup_LuisEr/4chanshit/img_arch.pkg/env/lib/python3.8/site-packages/urllib3/connectionpool.py", line 785, in urlopen
    retries = retries.increment(
  File "/home/luis/Code_Bakup_LuisEr/4chanshit/img_arch.pkg/env/lib/python3.8/site-packages/urllib3/util/retry.py", line 592, in increment
    raise MaxRetryError(_pool, url, error or ResponseError(cause))
urllib3.exceptions.MaxRetryError: HTTPConnectionPool(host='localhost', port=5050): Max retries exceeded with url: /data-images?tags=loli&page=1static/img/__9f3b725aa4c2c2c9b3f2a879508a629d.jpg (Caused by NewConnectionError('<urllib3.connection.HTTPConnection object at 0x7f50f5d197f0>: Failed to establish a new connection: [Errno 111] Connection refused'))

During handling of the above exception, another exception occurred:

Traceback (most recent call last):
  File "client.py", line 26, in inner_func
    response = request(cls, method, url, **kwargs)
  File "client.py", line 90, in request
    return super().request(*args, **kwargs)
  File "/home/luis/Code_Bakup_LuisEr/4chanshit/img_arch.pkg/env/lib/python3.8/site-packages/requests/sessions.py", line 529, in request
    resp = self.send(prep, **send_kwargs)
  File "/home/luis/Code_Bakup_LuisEr/4chanshit/img_arch.pkg/env/lib/python3.8/site-packages/requests/sessions.py", line 645, in send
    r = adapter.send(request, **kwargs)
  File "/home/luis/Code_Bakup_LuisEr/4chanshit/img_arch.pkg/env/lib/python3.8/site-packages/requests/adapters.py", line 519, in send
    raise ConnectionError(e, request=request)
requests.exceptions.ConnectionError: HTTPConnectionPool(host='localhost', port=5050): Max retries exceeded with url: /data-images?tags=loli&page=1static/img/__9f3b725aa4c2c2c9b3f2a879508a629d.jpg (Caused by NewConnectionError('<urllib3.connection.HTTPConnection object at 0x7f50f5d197f0>: Failed to establish a new connection: [Errno 111] Connection refused'))
2022-05-22 11:48:25,014 [ERROR] -- audit.Archive: Server URL: http://localhost:5050/data-images?tags=loli&page=1static/img/__9f3b725aa4c2c2c9b3f2a879508a629d.jpg, failed while trying to connect.
2022-05-22 11:48:25,219 [ERROR] -- audit.Archive: HTTPConnectionPool(host='localhost', port=5050): Max retries exceeded with url: /data-images?tags=loli&page=1static/img/__9f3b725aa4c2c2c9b3f2a879508a629d.jpg (Caused by NewConnectionError('<urllib3.connection.HTTPConnection object at 0x7f50f5ccb460>: Failed to establish a new connection: [Errno 111] Connection refused'))
Traceback (most recent call last):
  File "/home/luis/Code_Bakup_LuisEr/4chanshit/img_arch.pkg/env/lib/python3.8/site-packages/urllib3/connection.py", line 174, in _new_conn
    conn = connection.create_connection(
  File "/home/luis/Code_Bakup_LuisEr/4chanshit/img_arch.pkg/env/lib/python3.8/site-packages/urllib3/util/connection.py", line 95, in create_connection
    raise err
  File "/home/luis/Code_Bakup_LuisEr/4chanshit/img_arch.pkg/env/lib/python3.8/site-packages/urllib3/util/connection.py", line 85, in create_connection
    sock.connect(sa)
ConnectionRefusedError: [Errno 111] Connection refused

During handling of the above exception, another exception occurred:

Traceback (most recent call last):
  File "/home/luis/Code_Bakup_LuisEr/4chanshit/img_arch.pkg/env/lib/python3.8/site-packages/urllib3/connectionpool.py", line 703, in urlopen
    httplib_response = self._make_request(
  File "/home/luis/Code_Bakup_LuisEr/4chanshit/img_arch.pkg/env/lib/python3.8/site-packages/urllib3/connectionpool.py", line 398, in _make_request
    conn.request(method, url, **httplib_request_kw)
  File "/home/luis/Code_Bakup_LuisEr/4chanshit/img_arch.pkg/env/lib/python3.8/site-packages/urllib3/connection.py", line 239, in request
    super(HTTPConnection, self).request(method, url, body=body, headers=headers)
  File "/usr/lib64/python3.8/http/client.py", line 1252, in request
    self._send_request(method, url, body, headers, encode_chunked)
  File "/usr/lib64/python3.8/http/client.py", line 1298, in _send_request
    self.endheaders(body, encode_chunked=encode_chunked)
  File "/usr/lib64/python3.8/http/client.py", line 1247, in endheaders
    self._send_output(message_body, encode_chunked=encode_chunked)
  File "/usr/lib64/python3.8/http/client.py", line 1007, in _send_output
    self.send(msg)
  File "/usr/lib64/python3.8/http/client.py", line 947, in send
    self.connect()
  File "/home/luis/Code_Bakup_LuisEr/4chanshit/img_arch.pkg/env/lib/python3.8/site-packages/urllib3/connection.py", line 205, in connect
    conn = self._new_conn()
  File "/home/luis/Code_Bakup_LuisEr/4chanshit/img_arch.pkg/env/lib/python3.8/site-packages/urllib3/connection.py", line 186, in _new_conn
    raise NewConnectionError(
urllib3.exceptions.NewConnectionError: <urllib3.connection.HTTPConnection object at 0x7f50f5ccb460>: Failed to establish a new connection: [Errno 111] Connection refused

During handling of the above exception, another exception occurred:

Traceback (most recent call last):
  File "/home/luis/Code_Bakup_LuisEr/4chanshit/img_arch.pkg/env/lib/python3.8/site-packages/requests/adapters.py", line 440, in send
    resp = conn.urlopen(
  File "/home/luis/Code_Bakup_LuisEr/4chanshit/img_arch.pkg/env/lib/python3.8/site-packages/urllib3/connectionpool.py", line 785, in urlopen
    retries = retries.increment(
  File "/home/luis/Code_Bakup_LuisEr/4chanshit/img_arch.pkg/env/lib/python3.8/site-packages/urllib3/util/retry.py", line 592, in increment
    raise MaxRetryError(_pool, url, error or ResponseError(cause))
urllib3.exceptions.MaxRetryError: HTTPConnectionPool(host='localhost', port=5050): Max retries exceeded with url: /data-images?tags=loli&page=1static/img/__9f3b725aa4c2c2c9b3f2a879508a629d.jpg (Caused by NewConnectionError('<urllib3.connection.HTTPConnection object at 0x7f50f5ccb460>: Failed to establish a new connection: [Errno 111] Connection refused'))

During handling of the above exception, another exception occurred:

Traceback (most recent call last):
  File "client.py", line 26, in inner_func
    response = request(cls, method, url, **kwargs)
  File "client.py", line 90, in request
    return super().request(*args, **kwargs)
  File "/home/luis/Code_Bakup_LuisEr/4chanshit/img_arch.pkg/env/lib/python3.8/site-packages/requests/sessions.py", line 529, in request
    resp = self.send(prep, **send_kwargs)
  File "/home/luis/Code_Bakup_LuisEr/4chanshit/img_arch.pkg/env/lib/python3.8/site-packages/requests/sessions.py", line 645, in send
    r = adapter.send(request, **kwargs)
  File "/home/luis/Code_Bakup_LuisEr/4chanshit/img_arch.pkg/env/lib/python3.8/site-packages/requests/adapters.py", line 519, in send
    raise ConnectionError(e, request=request)
requests.exceptions.ConnectionError: HTTPConnectionPool(host='localhost', port=5050): Max retries exceeded with url: /data-images?tags=loli&page=1static/img/__9f3b725aa4c2c2c9b3f2a879508a629d.jpg (Caused by NewConnectionError('<urllib3.connection.HTTPConnection object at 0x7f50f5ccb460>: Failed to establish a new connection: [Errno 111] Connection refused'))
2022-05-22 11:48:25,221 [ERROR] -- audit.Archive: Server URL: http://localhost:5050/data-images?tags=loli&page=1static/img/__9f3b725aa4c2c2c9b3f2a879508a629d.jpg, failed while trying to connect.
2022-05-22 11:48:25,427 [ERROR] -- audit.Archive: HTTPConnectionPool(host='localhost', port=5050): Max retries exceeded with url: /data-images?tags=loli&page=1static/img/__9f3b725aa4c2c2c9b3f2a879508a629d.jpg (Caused by NewConnectionError('<urllib3.connection.HTTPConnection object at 0x7f50f5ccb820>: Failed to establish a new connection: [Errno 111] Connection refused'))
Traceback (most recent call last):
  File "/home/luis/Code_Bakup_LuisEr/4chanshit/img_arch.pkg/env/lib/python3.8/site-packages/urllib3/connection.py", line 174, in _new_conn
    conn = connection.create_connection(
  File "/home/luis/Code_Bakup_LuisEr/4chanshit/img_arch.pkg/env/lib/python3.8/site-packages/urllib3/util/connection.py", line 95, in create_connection
    raise err
  File "/home/luis/Code_Bakup_LuisEr/4chanshit/img_arch.pkg/env/lib/python3.8/site-packages/urllib3/util/connection.py", line 85, in create_connection
    sock.connect(sa)
ConnectionRefusedError: [Errno 111] Connection refused

During handling of the above exception, another exception occurred:

Traceback (most recent call last):
  File "/home/luis/Code_Bakup_LuisEr/4chanshit/img_arch.pkg/env/lib/python3.8/site-packages/urllib3/connectionpool.py", line 703, in urlopen
    httplib_response = self._make_request(
  File "/home/luis/Code_Bakup_LuisEr/4chanshit/img_arch.pkg/env/lib/python3.8/site-packages/urllib3/connectionpool.py", line 398, in _make_request
    conn.request(method, url, **httplib_request_kw)
  File "/home/luis/Code_Bakup_LuisEr/4chanshit/img_arch.pkg/env/lib/python3.8/site-packages/urllib3/connection.py", line 239, in request
    super(HTTPConnection, self).request(method, url, body=body, headers=headers)
  File "/usr/lib64/python3.8/http/client.py", line 1252, in request
    self._send_request(method, url, body, headers, encode_chunked)
  File "/usr/lib64/python3.8/http/client.py", line 1298, in _send_request
    self.endheaders(body, encode_chunked=encode_chunked)
  File "/usr/lib64/python3.8/http/client.py", line 1247, in endheaders
    self._send_output(message_body, encode_chunked=encode_chunked)
  File "/usr/lib64/python3.8/http/client.py", line 1007, in _send_output
    self.send(msg)
  File "/usr/lib64/python3.8/http/client.py", line 947, in send
    self.connect()
  File "/home/luis/Code_Bakup_LuisEr/4chanshit/img_arch.pkg/env/lib/python3.8/site-packages/urllib3/connection.py", line 205, in connect
    conn = self._new_conn()
  File "/home/luis/Code_Bakup_LuisEr/4chanshit/img_arch.pkg/env/lib/python3.8/site-packages/urllib3/connection.py", line 186, in _new_conn
    raise NewConnectionError(
urllib3.exceptions.NewConnectionError: <urllib3.connection.HTTPConnection object at 0x7f50f5ccb820>: Failed to establish a new connection: [Errno 111] Connection refused

During handling of the above exception, another exception occurred:

Traceback (most recent call last):
  File "/home/luis/Code_Bakup_LuisEr/4chanshit/img_arch.pkg/env/lib/python3.8/site-packages/requests/adapters.py", line 440, in send
    resp = conn.urlopen(
  File "/home/luis/Code_Bakup_LuisEr/4chanshit/img_arch.pkg/env/lib/python3.8/site-packages/urllib3/connectionpool.py", line 785, in urlopen
    retries = retries.increment(
  File "/home/luis/Code_Bakup_LuisEr/4chanshit/img_arch.pkg/env/lib/python3.8/site-packages/urllib3/util/retry.py", line 592, in increment
    raise MaxRetryError(_pool, url, error or ResponseError(cause))
urllib3.exceptions.MaxRetryError: HTTPConnectionPool(host='localhost', port=5050): Max retries exceeded with url: /data-images?tags=loli&page=1static/img/__9f3b725aa4c2c2c9b3f2a879508a629d.jpg (Caused by NewConnectionError('<urllib3.connection.HTTPConnection object at 0x7f50f5ccb820>: Failed to establish a new connection: [Errno 111] Connection refused'))

During handling of the above exception, another exception occurred:

Traceback (most recent call last):
  File "client.py", line 26, in inner_func
    response = request(cls, method, url, **kwargs)
  File "client.py", line 90, in request
    return super().request(*args, **kwargs)
  File "/home/luis/Code_Bakup_LuisEr/4chanshit/img_arch.pkg/env/lib/python3.8/site-packages/requests/sessions.py", line 529, in request
    resp = self.send(prep, **send_kwargs)
  File "/home/luis/Code_Bakup_LuisEr/4chanshit/img_arch.pkg/env/lib/python3.8/site-packages/requests/sessions.py", line 645, in send
    r = adapter.send(request, **kwargs)
  File "/home/luis/Code_Bakup_LuisEr/4chanshit/img_arch.pkg/env/lib/python3.8/site-packages/requests/adapters.py", line 519, in send
    raise ConnectionError(e, request=request)
requests.exceptions.ConnectionError: HTTPConnectionPool(host='localhost', port=5050): Max retries exceeded with url: /data-images?tags=loli&page=1static/img/__9f3b725aa4c2c2c9b3f2a879508a629d.jpg (Caused by NewConnectionError('<urllib3.connection.HTTPConnection object at 0x7f50f5ccb820>: Failed to establish a new connection: [Errno 111] Connection refused'))
2022-05-22 11:48:25,428 [ERROR] -- audit.Archive: Server URL: http://localhost:5050/data-images?tags=loli&page=1static/img/__9f3b725aa4c2c2c9b3f2a879508a629d.jpg, failed while trying to connect.
2022-05-22 11:48:25,634 [ERROR] -- audit.Archive: HTTPConnectionPool(host='localhost', port=5050): Max retries exceeded with url: /data-images?tags=loli&page=1static/img/__9f3b725aa4c2c2c9b3f2a879508a629d.jpg (Caused by NewConnectionError('<urllib3.connection.HTTPConnection object at 0x7f50f5cf13a0>: Failed to establish a new connection: [Errno 111] Connection refused'))
Traceback (most recent call last):
  File "/home/luis/Code_Bakup_LuisEr/4chanshit/img_arch.pkg/env/lib/python3.8/site-packages/urllib3/connection.py", line 174, in _new_conn
    conn = connection.create_connection(
  File "/home/luis/Code_Bakup_LuisEr/4chanshit/img_arch.pkg/env/lib/python3.8/site-packages/urllib3/util/connection.py", line 95, in create_connection
    raise err
  File "/home/luis/Code_Bakup_LuisEr/4chanshit/img_arch.pkg/env/lib/python3.8/site-packages/urllib3/util/connection.py", line 85, in create_connection
    sock.connect(sa)
ConnectionRefusedError: [Errno 111] Connection refused

During handling of the above exception, another exception occurred:

Traceback (most recent call last):
  File "/home/luis/Code_Bakup_LuisEr/4chanshit/img_arch.pkg/env/lib/python3.8/site-packages/urllib3/connectionpool.py", line 703, in urlopen
    httplib_response = self._make_request(
  File "/home/luis/Code_Bakup_LuisEr/4chanshit/img_arch.pkg/env/lib/python3.8/site-packages/urllib3/connectionpool.py", line 398, in _make_request
    conn.request(method, url, **httplib_request_kw)
  File "/home/luis/Code_Bakup_LuisEr/4chanshit/img_arch.pkg/env/lib/python3.8/site-packages/urllib3/connection.py", line 239, in request
    super(HTTPConnection, self).request(method, url, body=body, headers=headers)
  File "/usr/lib64/python3.8/http/client.py", line 1252, in request
    self._send_request(method, url, body, headers, encode_chunked)
  File "/usr/lib64/python3.8/http/client.py", line 1298, in _send_request
    self.endheaders(body, encode_chunked=encode_chunked)
  File "/usr/lib64/python3.8/http/client.py", line 1247, in endheaders
    self._send_output(message_body, encode_chunked=encode_chunked)
  File "/usr/lib64/python3.8/http/client.py", line 1007, in _send_output
    self.send(msg)
  File "/usr/lib64/python3.8/http/client.py", line 947, in send
    self.connect()
  File "/home/luis/Code_Bakup_LuisEr/4chanshit/img_arch.pkg/env/lib/python3.8/site-packages/urllib3/connection.py", line 205, in connect
    conn = self._new_conn()
  File "/home/luis/Code_Bakup_LuisEr/4chanshit/img_arch.pkg/env/lib/python3.8/site-packages/urllib3/connection.py", line 186, in _new_conn
    raise NewConnectionError(
urllib3.exceptions.NewConnectionError: <urllib3.connection.HTTPConnection object at 0x7f50f5cf13a0>: Failed to establish a new connection: [Errno 111] Connection refused

During handling of the above exception, another exception occurred:

Traceback (most recent call last):
  File "/home/luis/Code_Bakup_LuisEr/4chanshit/img_arch.pkg/env/lib/python3.8/site-packages/requests/adapters.py", line 440, in send
    resp = conn.urlopen(
  File "/home/luis/Code_Bakup_LuisEr/4chanshit/img_arch.pkg/env/lib/python3.8/site-packages/urllib3/connectionpool.py", line 785, in urlopen
    retries = retries.increment(
  File "/home/luis/Code_Bakup_LuisEr/4chanshit/img_arch.pkg/env/lib/python3.8/site-packages/urllib3/util/retry.py", line 592, in increment
    raise MaxRetryError(_pool, url, error or ResponseError(cause))
urllib3.exceptions.MaxRetryError: HTTPConnectionPool(host='localhost', port=5050): Max retries exceeded with url: /data-images?tags=loli&page=1static/img/__9f3b725aa4c2c2c9b3f2a879508a629d.jpg (Caused by NewConnectionError('<urllib3.connection.HTTPConnection object at 0x7f50f5cf13a0>: Failed to establish a new connection: [Errno 111] Connection refused'))

During handling of the above exception, another exception occurred:

Traceback (most recent call last):
  File "client.py", line 26, in inner_func
    response = request(cls, method, url, **kwargs)
  File "client.py", line 90, in request
    return super().request(*args, **kwargs)
  File "/home/luis/Code_Bakup_LuisEr/4chanshit/img_arch.pkg/env/lib/python3.8/site-packages/requests/sessions.py", line 529, in request
    resp = self.send(prep, **send_kwargs)
  File "/home/luis/Code_Bakup_LuisEr/4chanshit/img_arch.pkg/env/lib/python3.8/site-packages/requests/sessions.py", line 645, in send
    r = adapter.send(request, **kwargs)
  File "/home/luis/Code_Bakup_LuisEr/4chanshit/img_arch.pkg/env/lib/python3.8/site-packages/requests/adapters.py", line 519, in send
    raise ConnectionError(e, request=request)
requests.exceptions.ConnectionError: HTTPConnectionPool(host='localhost', port=5050): Max retries exceeded with url: /data-images?tags=loli&page=1static/img/__9f3b725aa4c2c2c9b3f2a879508a629d.jpg (Caused by NewConnectionError('<urllib3.connection.HTTPConnection object at 0x7f50f5cf13a0>: Failed to establish a new connection: [Errno 111] Connection refused'))
2022-05-22 11:48:25,636 [ERROR] -- audit.Archive: Server URL: http://localhost:5050/data-images?tags=loli&page=1static/img/__9f3b725aa4c2c2c9b3f2a879508a629d.jpg, failed while trying to connect.
2022-05-22 11:48:25,841 [ERROR] -- audit.Archive: HTTPConnectionPool(host='localhost', port=5050): Max retries exceeded with url: /data-images?tags=loli&page=1static/img/__9f3b725aa4c2c2c9b3f2a879508a629d.jpg (Caused by NewConnectionError('<urllib3.connection.HTTPConnection object at 0x7f50f5cf1130>: Failed to establish a new connection: [Errno 111] Connection refused'))
Traceback (most recent call last):
  File "/home/luis/Code_Bakup_LuisEr/4chanshit/img_arch.pkg/env/lib/python3.8/site-packages/urllib3/connection.py", line 174, in _new_conn
    conn = connection.create_connection(
  File "/home/luis/Code_Bakup_LuisEr/4chanshit/img_arch.pkg/env/lib/python3.8/site-packages/urllib3/util/connection.py", line 95, in create_connection
    raise err
  File "/home/luis/Code_Bakup_LuisEr/4chanshit/img_arch.pkg/env/lib/python3.8/site-packages/urllib3/util/connection.py", line 85, in create_connection
    sock.connect(sa)
ConnectionRefusedError: [Errno 111] Connection refused

During handling of the above exception, another exception occurred:

Traceback (most recent call last):
  File "/home/luis/Code_Bakup_LuisEr/4chanshit/img_arch.pkg/env/lib/python3.8/site-packages/urllib3/connectionpool.py", line 703, in urlopen
    httplib_response = self._make_request(
  File "/home/luis/Code_Bakup_LuisEr/4chanshit/img_arch.pkg/env/lib/python3.8/site-packages/urllib3/connectionpool.py", line 398, in _make_request
    conn.request(method, url, **httplib_request_kw)
  File "/home/luis/Code_Bakup_LuisEr/4chanshit/img_arch.pkg/env/lib/python3.8/site-packages/urllib3/connection.py", line 239, in request
    super(HTTPConnection, self).request(method, url, body=body, headers=headers)
  File "/usr/lib64/python3.8/http/client.py", line 1252, in request
    self._send_request(method, url, body, headers, encode_chunked)
  File "/usr/lib64/python3.8/http/client.py", line 1298, in _send_request
    self.endheaders(body, encode_chunked=encode_chunked)
  File "/usr/lib64/python3.8/http/client.py", line 1247, in endheaders
    self._send_output(message_body, encode_chunked=encode_chunked)
  File "/usr/lib64/python3.8/http/client.py", line 1007, in _send_output
    self.send(msg)
  File "/usr/lib64/python3.8/http/client.py", line 947, in send
    self.connect()
  File "/home/luis/Code_Bakup_LuisEr/4chanshit/img_arch.pkg/env/lib/python3.8/site-packages/urllib3/connection.py", line 205, in connect
    conn = self._new_conn()
  File "/home/luis/Code_Bakup_LuisEr/4chanshit/img_arch.pkg/env/lib/python3.8/site-packages/urllib3/connection.py", line 186, in _new_conn
    raise NewConnectionError(
urllib3.exceptions.NewConnectionError: <urllib3.connection.HTTPConnection object at 0x7f50f5cf1130>: Failed to establish a new connection: [Errno 111] Connection refused

During handling of the above exception, another exception occurred:

Traceback (most recent call last):
  File "/home/luis/Code_Bakup_LuisEr/4chanshit/img_arch.pkg/env/lib/python3.8/site-packages/requests/adapters.py", line 440, in send
    resp = conn.urlopen(
  File "/home/luis/Code_Bakup_LuisEr/4chanshit/img_arch.pkg/env/lib/python3.8/site-packages/urllib3/connectionpool.py", line 785, in urlopen
    retries = retries.increment(
  File "/home/luis/Code_Bakup_LuisEr/4chanshit/img_arch.pkg/env/lib/python3.8/site-packages/urllib3/util/retry.py", line 592, in increment
    raise MaxRetryError(_pool, url, error or ResponseError(cause))
urllib3.exceptions.MaxRetryError: HTTPConnectionPool(host='localhost', port=5050): Max retries exceeded with url: /data-images?tags=loli&page=1static/img/__9f3b725aa4c2c2c9b3f2a879508a629d.jpg (Caused by NewConnectionError('<urllib3.connection.HTTPConnection object at 0x7f50f5cf1130>: Failed to establish a new connection: [Errno 111] Connection refused'))

During handling of the above exception, another exception occurred:

Traceback (most recent call last):
  File "client.py", line 26, in inner_func
    response = request(cls, method, url, **kwargs)
  File "client.py", line 90, in request
    return super().request(*args, **kwargs)
  File "/home/luis/Code_Bakup_LuisEr/4chanshit/img_arch.pkg/env/lib/python3.8/site-packages/requests/sessions.py", line 529, in request
    resp = self.send(prep, **send_kwargs)
  File "/home/luis/Code_Bakup_LuisEr/4chanshit/img_arch.pkg/env/lib/python3.8/site-packages/requests/sessions.py", line 645, in send
    r = adapter.send(request, **kwargs)
  File "/home/luis/Code_Bakup_LuisEr/4chanshit/img_arch.pkg/env/lib/python3.8/site-packages/requests/adapters.py", line 519, in send
    raise ConnectionError(e, request=request)
requests.exceptions.ConnectionError: HTTPConnectionPool(host='localhost', port=5050): Max retries exceeded with url: /data-images?tags=loli&page=1static/img/__9f3b725aa4c2c2c9b3f2a879508a629d.jpg (Caused by NewConnectionError('<urllib3.connection.HTTPConnection object at 0x7f50f5cf1130>: Failed to establish a new connection: [Errno 111] Connection refused'))
2022-05-22 11:48:25,843 [ERROR] -- audit.Archive: Server URL: http://localhost:5050/data-images?tags=loli&page=1static/img/__9f3b725aa4c2c2c9b3f2a879508a629d.jpg, failed while trying to connect.
2022-05-22 11:48:26,049 [ERROR] -- audit.Archive: HTTPConnectionPool(host='localhost', port=5050): Max retries exceeded with url: /data-images?tags=loli&page=1static/img/__9f3b725aa4c2c2c9b3f2a879508a629d.jpg (Caused by NewConnectionError('<urllib3.connection.HTTPConnection object at 0x7f50f5cf18e0>: Failed to establish a new connection: [Errno 111] Connection refused'))
Traceback (most recent call last):
  File "/home/luis/Code_Bakup_LuisEr/4chanshit/img_arch.pkg/env/lib/python3.8/site-packages/urllib3/connection.py", line 174, in _new_conn
    conn = connection.create_connection(
  File "/home/luis/Code_Bakup_LuisEr/4chanshit/img_arch.pkg/env/lib/python3.8/site-packages/urllib3/util/connection.py", line 95, in create_connection
    raise err
  File "/home/luis/Code_Bakup_LuisEr/4chanshit/img_arch.pkg/env/lib/python3.8/site-packages/urllib3/util/connection.py", line 85, in create_connection
    sock.connect(sa)
ConnectionRefusedError: [Errno 111] Connection refused

During handling of the above exception, another exception occurred:

Traceback (most recent call last):
  File "/home/luis/Code_Bakup_LuisEr/4chanshit/img_arch.pkg/env/lib/python3.8/site-packages/urllib3/connectionpool.py", line 703, in urlopen
    httplib_response = self._make_request(
  File "/home/luis/Code_Bakup_LuisEr/4chanshit/img_arch.pkg/env/lib/python3.8/site-packages/urllib3/connectionpool.py", line 398, in _make_request
    conn.request(method, url, **httplib_request_kw)
  File "/home/luis/Code_Bakup_LuisEr/4chanshit/img_arch.pkg/env/lib/python3.8/site-packages/urllib3/connection.py", line 239, in request
    super(HTTPConnection, self).request(method, url, body=body, headers=headers)
  File "/usr/lib64/python3.8/http/client.py", line 1252, in request
    self._send_request(method, url, body, headers, encode_chunked)
  File "/usr/lib64/python3.8/http/client.py", line 1298, in _send_request
    self.endheaders(body, encode_chunked=encode_chunked)
  File "/usr/lib64/python3.8/http/client.py", line 1247, in endheaders
    self._send_output(message_body, encode_chunked=encode_chunked)
  File "/usr/lib64/python3.8/http/client.py", line 1007, in _send_output
    self.send(msg)
  File "/usr/lib64/python3.8/http/client.py", line 947, in send
    self.connect()
  File "/home/luis/Code_Bakup_LuisEr/4chanshit/img_arch.pkg/env/lib/python3.8/site-packages/urllib3/connection.py", line 205, in connect
    conn = self._new_conn()
  File "/home/luis/Code_Bakup_LuisEr/4chanshit/img_arch.pkg/env/lib/python3.8/site-packages/urllib3/connection.py", line 186, in _new_conn
    raise NewConnectionError(
urllib3.exceptions.NewConnectionError: <urllib3.connection.HTTPConnection object at 0x7f50f5cf18e0>: Failed to establish a new connection: [Errno 111] Connection refused

During handling of the above exception, another exception occurred:

Traceback (most recent call last):
  File "/home/luis/Code_Bakup_LuisEr/4chanshit/img_arch.pkg/env/lib/python3.8/site-packages/requests/adapters.py", line 440, in send
    resp = conn.urlopen(
  File "/home/luis/Code_Bakup_LuisEr/4chanshit/img_arch.pkg/env/lib/python3.8/site-packages/urllib3/connectionpool.py", line 785, in urlopen
    retries = retries.increment(
  File "/home/luis/Code_Bakup_LuisEr/4chanshit/img_arch.pkg/env/lib/python3.8/site-packages/urllib3/util/retry.py", line 592, in increment
    raise MaxRetryError(_pool, url, error or ResponseError(cause))
urllib3.exceptions.MaxRetryError: HTTPConnectionPool(host='localhost', port=5050): Max retries exceeded with url: /data-images?tags=loli&page=1static/img/__9f3b725aa4c2c2c9b3f2a879508a629d.jpg (Caused by NewConnectionError('<urllib3.connection.HTTPConnection object at 0x7f50f5cf18e0>: Failed to establish a new connection: [Errno 111] Connection refused'))

During handling of the above exception, another exception occurred:

Traceback (most recent call last):
  File "client.py", line 26, in inner_func
    response = request(cls, method, url, **kwargs)
  File "client.py", line 90, in request
    return super().request(*args, **kwargs)
  File "/home/luis/Code_Bakup_LuisEr/4chanshit/img_arch.pkg/env/lib/python3.8/site-packages/requests/sessions.py", line 529, in request
    resp = self.send(prep, **send_kwargs)
  File "/home/luis/Code_Bakup_LuisEr/4chanshit/img_arch.pkg/env/lib/python3.8/site-packages/requests/sessions.py", line 645, in send
    r = adapter.send(request, **kwargs)
  File "/home/luis/Code_Bakup_LuisEr/4chanshit/img_arch.pkg/env/lib/python3.8/site-packages/requests/adapters.py", line 519, in send
    raise ConnectionError(e, request=request)
requests.exceptions.ConnectionError: HTTPConnectionPool(host='localhost', port=5050): Max retries exceeded with url: /data-images?tags=loli&page=1static/img/__9f3b725aa4c2c2c9b3f2a879508a629d.jpg (Caused by NewConnectionError('<urllib3.connection.HTTPConnection object at 0x7f50f5cf18e0>: Failed to establish a new connection: [Errno 111] Connection refused'))
2022-05-22 11:48:26,051 [ERROR] -- audit.Archive: Server URL: http://localhost:5050/data-images?tags=loli&page=1static/img/__9f3b725aa4c2c2c9b3f2a879508a629d.jpg, failed while trying to connect.
2022-05-22 11:48:26,255 [ERROR] -- audit.Archive: HTTPConnectionPool(host='localhost', port=5050): Max retries exceeded with url: /data-images?tags=loli&page=1static/img/__9f3b725aa4c2c2c9b3f2a879508a629d.jpg (Caused by NewConnectionError('<urllib3.connection.HTTPConnection object at 0x7f50f5cf1b80>: Failed to establish a new connection: [Errno 111] Connection refused'))
Traceback (most recent call last):
  File "/home/luis/Code_Bakup_LuisEr/4chanshit/img_arch.pkg/env/lib/python3.8/site-packages/urllib3/connection.py", line 174, in _new_conn
    conn = connection.create_connection(
  File "/home/luis/Code_Bakup_LuisEr/4chanshit/img_arch.pkg/env/lib/python3.8/site-packages/urllib3/util/connection.py", line 95, in create_connection
    raise err
  File "/home/luis/Code_Bakup_LuisEr/4chanshit/img_arch.pkg/env/lib/python3.8/site-packages/urllib3/util/connection.py", line 85, in create_connection
    sock.connect(sa)
ConnectionRefusedError: [Errno 111] Connection refused

During handling of the above exception, another exception occurred:

Traceback (most recent call last):
  File "/home/luis/Code_Bakup_LuisEr/4chanshit/img_arch.pkg/env/lib/python3.8/site-packages/urllib3/connectionpool.py", line 703, in urlopen
    httplib_response = self._make_request(
  File "/home/luis/Code_Bakup_LuisEr/4chanshit/img_arch.pkg/env/lib/python3.8/site-packages/urllib3/connectionpool.py", line 398, in _make_request
    conn.request(method, url, **httplib_request_kw)
  File "/home/luis/Code_Bakup_LuisEr/4chanshit/img_arch.pkg/env/lib/python3.8/site-packages/urllib3/connection.py", line 239, in request
    super(HTTPConnection, self).request(method, url, body=body, headers=headers)
  File "/usr/lib64/python3.8/http/client.py", line 1252, in request
    self._send_request(method, url, body, headers, encode_chunked)
  File "/usr/lib64/python3.8/http/client.py", line 1298, in _send_request
    self.endheaders(body, encode_chunked=encode_chunked)
  File "/usr/lib64/python3.8/http/client.py", line 1247, in endheaders
    self._send_output(message_body, encode_chunked=encode_chunked)
  File "/usr/lib64/python3.8/http/client.py", line 1007, in _send_output
    self.send(msg)
  File "/usr/lib64/python3.8/http/client.py", line 947, in send
    self.connect()
  File "/home/luis/Code_Bakup_LuisEr/4chanshit/img_arch.pkg/env/lib/python3.8/site-packages/urllib3/connection.py", line 205, in connect
    conn = self._new_conn()
  File "/home/luis/Code_Bakup_LuisEr/4chanshit/img_arch.pkg/env/lib/python3.8/site-packages/urllib3/connection.py", line 186, in _new_conn
    raise NewConnectionError(
urllib3.exceptions.NewConnectionError: <urllib3.connection.HTTPConnection object at 0x7f50f5cf1b80>: Failed to establish a new connection: [Errno 111] Connection refused

During handling of the above exception, another exception occurred:

Traceback (most recent call last):
  File "/home/luis/Code_Bakup_LuisEr/4chanshit/img_arch.pkg/env/lib/python3.8/site-packages/requests/adapters.py", line 440, in send
    resp = conn.urlopen(
  File "/home/luis/Code_Bakup_LuisEr/4chanshit/img_arch.pkg/env/lib/python3.8/site-packages/urllib3/connectionpool.py", line 785, in urlopen
    retries = retries.increment(
  File "/home/luis/Code_Bakup_LuisEr/4chanshit/img_arch.pkg/env/lib/python3.8/site-packages/urllib3/util/retry.py", line 592, in increment
    raise MaxRetryError(_pool, url, error or ResponseError(cause))
urllib3.exceptions.MaxRetryError: HTTPConnectionPool(host='localhost', port=5050): Max retries exceeded with url: /data-images?tags=loli&page=1static/img/__9f3b725aa4c2c2c9b3f2a879508a629d.jpg (Caused by NewConnectionError('<urllib3.connection.HTTPConnection object at 0x7f50f5cf1b80>: Failed to establish a new connection: [Errno 111] Connection refused'))

During handling of the above exception, another exception occurred:

Traceback (most recent call last):
  File "client.py", line 26, in inner_func
    response = request(cls, method, url, **kwargs)
  File "client.py", line 90, in request
    return super().request(*args, **kwargs)
  File "/home/luis/Code_Bakup_LuisEr/4chanshit/img_arch.pkg/env/lib/python3.8/site-packages/requests/sessions.py", line 529, in request
    resp = self.send(prep, **send_kwargs)
  File "/home/luis/Code_Bakup_LuisEr/4chanshit/img_arch.pkg/env/lib/python3.8/site-packages/requests/sessions.py", line 645, in send
    r = adapter.send(request, **kwargs)
  File "/home/luis/Code_Bakup_LuisEr/4chanshit/img_arch.pkg/env/lib/python3.8/site-packages/requests/adapters.py", line 519, in send
    raise ConnectionError(e, request=request)
requests.exceptions.ConnectionError: HTTPConnectionPool(host='localhost', port=5050): Max retries exceeded with url: /data-images?tags=loli&page=1static/img/__9f3b725aa4c2c2c9b3f2a879508a629d.jpg (Caused by NewConnectionError('<urllib3.connection.HTTPConnection object at 0x7f50f5cf1b80>: Failed to establish a new connection: [Errno 111] Connection refused'))
2022-05-22 11:48:26,257 [ERROR] -- audit.Archive: Server URL: http://localhost:5050/data-images?tags=loli&page=1static/img/__9f3b725aa4c2c2c9b3f2a879508a629d.jpg, failed while trying to connect.
2022-05-22 11:48:26,461 [ERROR] -- audit.Archive: HTTPConnectionPool(host='localhost', port=5050): Max retries exceeded with url: /data-images?tags=loli&page=1static/img/__9f3b725aa4c2c2c9b3f2a879508a629d.jpg (Caused by NewConnectionError('<urllib3.connection.HTTPConnection object at 0x7f50f5cdc700>: Failed to establish a new connection: [Errno 111] Connection refused'))
Traceback (most recent call last):
  File "/home/luis/Code_Bakup_LuisEr/4chanshit/img_arch.pkg/env/lib/python3.8/site-packages/urllib3/connection.py", line 174, in _new_conn
    conn = connection.create_connection(
  File "/home/luis/Code_Bakup_LuisEr/4chanshit/img_arch.pkg/env/lib/python3.8/site-packages/urllib3/util/connection.py", line 95, in create_connection
    raise err
  File "/home/luis/Code_Bakup_LuisEr/4chanshit/img_arch.pkg/env/lib/python3.8/site-packages/urllib3/util/connection.py", line 85, in create_connection
    sock.connect(sa)
ConnectionRefusedError: [Errno 111] Connection refused

During handling of the above exception, another exception occurred:

Traceback (most recent call last):
  File "/home/luis/Code_Bakup_LuisEr/4chanshit/img_arch.pkg/env/lib/python3.8/site-packages/urllib3/connectionpool.py", line 703, in urlopen
    httplib_response = self._make_request(
  File "/home/luis/Code_Bakup_LuisEr/4chanshit/img_arch.pkg/env/lib/python3.8/site-packages/urllib3/connectionpool.py", line 398, in _make_request
    conn.request(method, url, **httplib_request_kw)
  File "/home/luis/Code_Bakup_LuisEr/4chanshit/img_arch.pkg/env/lib/python3.8/site-packages/urllib3/connection.py", line 239, in request
    super(HTTPConnection, self).request(method, url, body=body, headers=headers)
  File "/usr/lib64/python3.8/http/client.py", line 1252, in request
    self._send_request(method, url, body, headers, encode_chunked)
  File "/usr/lib64/python3.8/http/client.py", line 1298, in _send_request
    self.endheaders(body, encode_chunked=encode_chunked)
  File "/usr/lib64/python3.8/http/client.py", line 1247, in endheaders
    self._send_output(message_body, encode_chunked=encode_chunked)
  File "/usr/lib64/python3.8/http/client.py", line 1007, in _send_output
    self.send(msg)
  File "/usr/lib64/python3.8/http/client.py", line 947, in send
    self.connect()
  File "/home/luis/Code_Bakup_LuisEr/4chanshit/img_arch.pkg/env/lib/python3.8/site-packages/urllib3/connection.py", line 205, in connect
    conn = self._new_conn()
  File "/home/luis/Code_Bakup_LuisEr/4chanshit/img_arch.pkg/env/lib/python3.8/site-packages/urllib3/connection.py", line 186, in _new_conn
    raise NewConnectionError(
urllib3.exceptions.NewConnectionError: <urllib3.connection.HTTPConnection object at 0x7f50f5cdc700>: Failed to establish a new connection: [Errno 111] Connection refused

During handling of the above exception, another exception occurred:

Traceback (most recent call last):
  File "/home/luis/Code_Bakup_LuisEr/4chanshit/img_arch.pkg/env/lib/python3.8/site-packages/requests/adapters.py", line 440, in send
    resp = conn.urlopen(
  File "/home/luis/Code_Bakup_LuisEr/4chanshit/img_arch.pkg/env/lib/python3.8/site-packages/urllib3/connectionpool.py", line 785, in urlopen
    retries = retries.increment(
  File "/home/luis/Code_Bakup_LuisEr/4chanshit/img_arch.pkg/env/lib/python3.8/site-packages/urllib3/util/retry.py", line 592, in increment
    raise MaxRetryError(_pool, url, error or ResponseError(cause))
urllib3.exceptions.MaxRetryError: HTTPConnectionPool(host='localhost', port=5050): Max retries exceeded with url: /data-images?tags=loli&page=1static/img/__9f3b725aa4c2c2c9b3f2a879508a629d.jpg (Caused by NewConnectionError('<urllib3.connection.HTTPConnection object at 0x7f50f5cdc700>: Failed to establish a new connection: [Errno 111] Connection refused'))

During handling of the above exception, another exception occurred:

Traceback (most recent call last):
  File "client.py", line 26, in inner_func
    response = request(cls, method, url, **kwargs)
  File "client.py", line 90, in request
    return super().request(*args, **kwargs)
  File "/home/luis/Code_Bakup_LuisEr/4chanshit/img_arch.pkg/env/lib/python3.8/site-packages/requests/sessions.py", line 529, in request
    resp = self.send(prep, **send_kwargs)
  File "/home/luis/Code_Bakup_LuisEr/4chanshit/img_arch.pkg/env/lib/python3.8/site-packages/requests/sessions.py", line 645, in send
    r = adapter.send(request, **kwargs)
  File "/home/luis/Code_Bakup_LuisEr/4chanshit/img_arch.pkg/env/lib/python3.8/site-packages/requests/adapters.py", line 519, in send
    raise ConnectionError(e, request=request)
requests.exceptions.ConnectionError: HTTPConnectionPool(host='localhost', port=5050): Max retries exceeded with url: /data-images?tags=loli&page=1static/img/__9f3b725aa4c2c2c9b3f2a879508a629d.jpg (Caused by NewConnectionError('<urllib3.connection.HTTPConnection object at 0x7f50f5cdc700>: Failed to establish a new connection: [Errno 111] Connection refused'))
2022-05-22 11:48:26,463 [ERROR] -- audit.Archive: Server URL: http://localhost:5050/data-images?tags=loli&page=1static/img/__9f3b725aa4c2c2c9b3f2a879508a629d.jpg, failed while trying to connect.
2022-05-22 11:48:26,667 [ERROR] -- audit.Archive: HTTPConnectionPool(host='localhost', port=5050): Max retries exceeded with url: /data-images?tags=loli&page=1static/img/__9f3b725aa4c2c2c9b3f2a879508a629d.jpg (Caused by NewConnectionError('<urllib3.connection.HTTPConnection object at 0x7f50f5cdc850>: Failed to establish a new connection: [Errno 111] Connection refused'))
Traceback (most recent call last):
  File "/home/luis/Code_Bakup_LuisEr/4chanshit/img_arch.pkg/env/lib/python3.8/site-packages/urllib3/connection.py", line 174, in _new_conn
    conn = connection.create_connection(
  File "/home/luis/Code_Bakup_LuisEr/4chanshit/img_arch.pkg/env/lib/python3.8/site-packages/urllib3/util/connection.py", line 95, in create_connection
    raise err
  File "/home/luis/Code_Bakup_LuisEr/4chanshit/img_arch.pkg/env/lib/python3.8/site-packages/urllib3/util/connection.py", line 85, in create_connection
    sock.connect(sa)
ConnectionRefusedError: [Errno 111] Connection refused

During handling of the above exception, another exception occurred:

Traceback (most recent call last):
  File "/home/luis/Code_Bakup_LuisEr/4chanshit/img_arch.pkg/env/lib/python3.8/site-packages/urllib3/connectionpool.py", line 703, in urlopen
    httplib_response = self._make_request(
  File "/home/luis/Code_Bakup_LuisEr/4chanshit/img_arch.pkg/env/lib/python3.8/site-packages/urllib3/connectionpool.py", line 398, in _make_request
    conn.request(method, url, **httplib_request_kw)
  File "/home/luis/Code_Bakup_LuisEr/4chanshit/img_arch.pkg/env/lib/python3.8/site-packages/urllib3/connection.py", line 239, in request
    super(HTTPConnection, self).request(method, url, body=body, headers=headers)
  File "/usr/lib64/python3.8/http/client.py", line 1252, in request
    self._send_request(method, url, body, headers, encode_chunked)
  File "/usr/lib64/python3.8/http/client.py", line 1298, in _send_request
    self.endheaders(body, encode_chunked=encode_chunked)
  File "/usr/lib64/python3.8/http/client.py", line 1247, in endheaders
    self._send_output(message_body, encode_chunked=encode_chunked)
  File "/usr/lib64/python3.8/http/client.py", line 1007, in _send_output
    self.send(msg)
  File "/usr/lib64/python3.8/http/client.py", line 947, in send
    self.connect()
  File "/home/luis/Code_Bakup_LuisEr/4chanshit/img_arch.pkg/env/lib/python3.8/site-packages/urllib3/connection.py", line 205, in connect
    conn = self._new_conn()
  File "/home/luis/Code_Bakup_LuisEr/4chanshit/img_arch.pkg/env/lib/python3.8/site-packages/urllib3/connection.py", line 186, in _new_conn
    raise NewConnectionError(
urllib3.exceptions.NewConnectionError: <urllib3.connection.HTTPConnection object at 0x7f50f5cdc850>: Failed to establish a new connection: [Errno 111] Connection refused

During handling of the above exception, another exception occurred:

Traceback (most recent call last):
  File "/home/luis/Code_Bakup_LuisEr/4chanshit/img_arch.pkg/env/lib/python3.8/site-packages/requests/adapters.py", line 440, in send
    resp = conn.urlopen(
  File "/home/luis/Code_Bakup_LuisEr/4chanshit/img_arch.pkg/env/lib/python3.8/site-packages/urllib3/connectionpool.py", line 785, in urlopen
    retries = retries.increment(
  File "/home/luis/Code_Bakup_LuisEr/4chanshit/img_arch.pkg/env/lib/python3.8/site-packages/urllib3/util/retry.py", line 592, in increment
    raise MaxRetryError(_pool, url, error or ResponseError(cause))
urllib3.exceptions.MaxRetryError: HTTPConnectionPool(host='localhost', port=5050): Max retries exceeded with url: /data-images?tags=loli&page=1static/img/__9f3b725aa4c2c2c9b3f2a879508a629d.jpg (Caused by NewConnectionError('<urllib3.connection.HTTPConnection object at 0x7f50f5cdc850>: Failed to establish a new connection: [Errno 111] Connection refused'))

During handling of the above exception, another exception occurred:

Traceback (most recent call last):
  File "client.py", line 26, in inner_func
    response = request(cls, method, url, **kwargs)
  File "client.py", line 90, in request
    return super().request(*args, **kwargs)
  File "/home/luis/Code_Bakup_LuisEr/4chanshit/img_arch.pkg/env/lib/python3.8/site-packages/requests/sessions.py", line 529, in request
    resp = self.send(prep, **send_kwargs)
  File "/home/luis/Code_Bakup_LuisEr/4chanshit/img_arch.pkg/env/lib/python3.8/site-packages/requests/sessions.py", line 645, in send
    r = adapter.send(request, **kwargs)
  File "/home/luis/Code_Bakup_LuisEr/4chanshit/img_arch.pkg/env/lib/python3.8/site-packages/requests/adapters.py", line 519, in send
    raise ConnectionError(e, request=request)
requests.exceptions.ConnectionError: HTTPConnectionPool(host='localhost', port=5050): Max retries exceeded with url: /data-images?tags=loli&page=1static/img/__9f3b725aa4c2c2c9b3f2a879508a629d.jpg (Caused by NewConnectionError('<urllib3.connection.HTTPConnection object at 0x7f50f5cdc850>: Failed to establish a new connection: [Errno 111] Connection refused'))
2022-05-22 11:48:26,668 [ERROR] -- audit.Archive: Server URL: http://localhost:5050/data-images?tags=loli&page=1static/img/__9f3b725aa4c2c2c9b3f2a879508a629d.jpg, failed while trying to connect.
